Workbook

Sheet LEYENDA_PARA_DESARROLLO
A1: PLANTILLA — PLANILLA DE PROCESO (CTN) — v3
A2: Esta hoja es solo documentación. No se exporta.
A4: Hojas de datos: | B4: PLANTILLA_ETAPA_1 y PLANTILLA_ETAPA_2 (una por etapa, con forma distinta cada una).
A6: — ESTRUCTURA COMÚN A AMBAS ETAPAS —
A7: Fila de encabezado de mes | B7: Fila 6
A8: Fila de título de instrumento (tarea) | B8: Fila 7 (texto rotado 90°, wrapText=true)
A9: Fila TP (puntaje máximo por instrumento) | B9: Fila 8
A10: Primera fila de alumno | B10: Fila 9 (agregar/quitar filas debajo)
A11: Bloque de mes en la plantilla | B11: 1 solo bloque de EJEMPLO (8 columnas de tarea + 1 Subtotal = 9 columnas). El código debe clonarlo dinámicamente una vez por cada mes real con tareas, ajustando la cantidad de columnas de tarea (máx. observado 12) — no hay una cantidad fija de bloques de mes en la plantilla.
A13: — ETAPA 1 (hoja PLANTILLA_ETAPA_1) — SIN columna fija antes de los meses —
A14: Columna N° | B14: A
A15: Columna Apellidos y Nombres | B15: B
A16: Primer mes (bloque de ejemplo) | B16: Columna C:K (C:J = 8 tareas, K = Subtotal)
A17: Columna Total General | B17: Columna L (después del último bloque de mes real)
A18: Columna Calificación Final 1ª Etapa | B18: Columna M (después de Total General)
A19: Freeze panes | B19: 2 columnas fijas (A:B) + fila TP → sheet.createFreezePane(2, 8) → celda C9
A21: — ETAPA 2 (hoja PLANTILLA_ETAPA_2) — SÍ tiene una columna fija antes de los meses —
A22: Columna N° | B22: A
A23: Columna Apellidos y Nombres | B23: B
A24: Columna Calificación Final 1ª Etapa (heredada) | B24: Columna C — antes del primer mes, NO después
A25: Primer mes (bloque de ejemplo) | B25: Columna D:L (D:K = 8 tareas, L = Subtotal)
A26: Columna Total General | B26: Columna M (después del último bloque de mes real)
A27: Columna Calificación Final 2ª Etapa | B27: Columna N
A28: Columna Sumatoria 1° y 2° Etapa | B28: Columna O
A29: Columna Calificación Final (promedio) | B29: Columna P
A30: Columna Período Complementario | B30: Columna Q (sin dato de origen aún — opcional, carga manual)
A31: Columna Período Regularización | B31: Columna R (sin dato de origen aún — opcional, carga manual)
A32: Freeze panes | B32: 3 columnas fijas (A:C, incluye Calificación Final 1ª Etapa) + fila TP → sheet.createFreezePane(3, 8) → celda D9 — DISTINTO de Etapa 1, no usar el mismo valor fijo para ambas hojas
A34: — IMPORTANTE: applyNavigationAndVisualDesign debe recibir la etapa —
A35: createFreezePane hardcodeado en columna 2 | B35: BUG: el método de referencia congela siempre en la columna 2 (createFreezePane(2, TP_ROW)); para ETAPA_2 tiene que ser columna 3. Pasar un parámetro firstMonthCol (o directamente resolverlo desde monthBlocks.get(0).startCol) en vez de asumir 2 fijo.
A36: lastCol / piso fijo en columna AC | B36: BUG: el cálculo de lastCol para zebra striping y posición del logo (Math.max(..., columnIndexFromLetter("AC"))) asume un piso fijo pensado para la plantilla ancha vieja (columnas de 13 caracteres). Con las columnas angostas nuevas (6.5/7.5 caracteres) ese piso ya no tiene sentido, y además no suma las columnas fijas de cola específicas de cada etapa (2 en Etapa 1, 6 en Etapa 2). lastCol debe calcularse como: último subtotalCol de mes + cantidad de columnas fijas de cola de esa etapa (trailingCols), sin piso fijo en "AC".
A38: — MARCADORES {{...}} A REEMPLAZAR POR EL PROGRAMA —
A39: {{DISCIPLINA}} | B39: materia.getNombre() (o el nombre de la disciplina)
A40: {{ESPECIALIDAD}} | B40: curso.getEspecialidad()
A41: {{PROFESOR}} | B41: user.getFullName()
A42: {{CURSO}} / {{TURNO}} / {{SECCION}} | B42: curso.getCursoOrdinal() / turno / curso.getSeccion()
A43: {{ANIO}} | B43: AcademicPeriod.current() o el año de la planilla
A44: {{MES_n_NOMBRE}} | B44: Nombre del mes, agrupando las Tarea por Tarea.getFecha().getMonth()
A45: {{MES_n_INSTR_j}} | B45: Tarea.getTitulo() de la j-ésima tarea de ese mes
A46: {{ALUMNO_NOMBRE}} | B46: StudentRow.getAlumnoNombre()
...

Sheet PLANTILLA_ETAPA_1
A1: COLEGIO TÉCNICO NACIONAL DE ASUNCIÓN | Q1: NOTA PARA EL AGENTE (ETAPA 1): el bloque de mes (columnas C:K) es el patron a clonar por cada mes real, igual criterio que en PLANTILLA_ETAPA_2. Esta hoja NO tiene columna fija antes de los meses (el primer mes arranca justo despues de Apellidos y Nombres), por eso el freeze pane cubre solo 2 columnas fijas (A:B), no 3 como en ETAPA_2. Las columnas fijas DESPUES del ultimo mes son distintas de ETAPA_2: aqui solo hay Total General y Calificacion Final 1a Etapa (2 columnas), mientras que ETAPA_2 tiene 6. El lastCol para zebra striping / logo debe calcularse por separado para cada hoja, sumando estas columnas fijas especificas de cada etapa - un unico valor compartido (como el piso fijo en columna AC del metodo original) no sirve para ambas. Esta nota es solo de referencia, no debe copiarse a la plantilla real.
A2: Servicio de Evaluación
A3: PLANILLA DE PROCESO - 1º ETAPA
A4: Disciplina: {{DISCIPLINA}} | C4: Especialidad: {{ESPECIALIDAD}}
A5: Profesor/a: {{PROFESOR}} | C5: Curso: {{CURSO}}° Turno: {{TURNO}} Sección: "{{SECCION}}" | I5: Año: {{ANIO}}
A6: N° | B6: Apellidos y Nombres | C6: {{MES_1_NOMBRE}} | K6: Subtotal | L6: Total General | M6: Calificación Final 1º Etapa
C7: {{MES_1_INSTR_1}} | D7: {{MES_1_INSTR_2}} | E7: {{MES_1_INSTR_3}} | F7: {{MES_1_INSTR_4}} | G7: {{MES_1_INSTR_5}} | H7: {{MES_1_INSTR_6}} | I7: {{MES_1_INSTR_7}} | J7: {{MES_1_INSTR_8}}
A8: TP | B8: (puntaje máximo) | C8: 0 | D8: 0 | E8: 0 | F8: 0 | G8: 0 | H8: 0 | I8: 0 | J8: 0 | K8: =SUM(C8:J8) -> 0 | L8: =SUM(K8) -> 0
A9: 1 | B9: {{ALUMNO_NOMBRE}} | C9: 0 | D9: 0 | E9: 0 | F9: 0 | G9: 0 | H9: 0 | I9: 0 | J9: 0 | K9: =SUM(C9:J9) -> 0 | L9: =K9 -> 0 | M9: 0
A10: 2 | B10: {{ALUMNO_NOMBRE}} | C10: 0 | D10: 0 | E10: 0 | F10: 0 | G10: 0 | H10: 0 | I10: 0 | J10: 0 | K10: =SUM(C10:J10) -> 0 | L10: =K10 -> 0 | M10: 0
A11: 3 | B11: {{ALUMNO_NOMBRE}} | C11: 0 | D11: 0 | E11: 0 | F11: 0 | G11: 0 | H11: 0 | I11: 0 | J11: 0 | K11: =SUM(C11:J11) -> 0 | L11: =K11 -> 0 | M11: 0
A12: 4 | B12: {{ALUMNO_NOMBRE}} | C12: 0 | D12: 0 | E12: 0 | F12: 0 | G12: 0 | H12: 0 | I12: 0 | J12: 0 | K12: =SUM(C12:J12) -> 0 | L12: =K12 -> 0 | M12: 0
A13: 5 | B13: {{ALUMNO_NOMBRE}} | C13: 0 | D13: 0 | E13: 0 | F13: 0 | G13: 0 | H13: 0 | I13: 0 | J13: 0 | K13: =SUM(C13:J13) -> 0 | L13: =K13 -> 0 | M13: 0

Sheet PLANTILLA_ETAPA_2
A1: COLEGIO TÉCNICO NACIONAL DE ASUNCIÓN | T1: NOTA PARA EL AGENTE (ETAPA 2): el bloque de mes (columnas D:L) es el patron a clonar por cada mes real - repetir estructura, estilos, agrupacion y borde de bloque, ajustando la cantidad de columnas de tarea. A diferencia de PLANTILLA_ETAPA_1, esta hoja tiene una columna fija ANTES de los meses (C = Calificacion Final 1a Etapa), por lo que el primer mes real arranca en la columna D, no en C, y el freeze pane debe cubrir 3 columnas fijas (A:C) en vez de 2. Ademas tiene columnas fijas DESPUES del ultimo mes que ETAPA_1 no tiene: Total General, Calificacion Final 2a Etapa, Sumatoria 1 y 2 Etapa, Calificacion Final, Periodo Complementario y Periodo Regularizacion. El calculo de lastCol para zebra striping / logo debe sumar estas columnas fijas ademas del ultimo bloque de mes, no solo tomar el maximo entre bloques de mes y una columna piso fija tipo AC. Esta nota es solo de referencia, no debe copiarse a la plantilla real.
A2: Servicio de Evaluación
A3: PLANILLA DE PROCESO - 2º ETAPA
A4: Disciplina: {{DISCIPLINA}} | C4: Especialidad: {{ESPECIALIDAD}}
A5: Profesor/a: {{PROFESOR}} | C5: Curso: {{CURSO}}° Turno: {{TURNO}} Sección: "{{SECCION}}" | I5: Año: {{ANIO}}
A6: N° | B6: Apellidos y Nombres | C6: Calificación Final 1º Etapa | D6: {{MES_1_NOMBRE}} | L6: Subtotal | M6: Total General | N6: Calificación Final 2º Etapa | O6: Sumatoria 1° y 2° Etapa | P6: Calificación Final | Q6: Período Complementario | R6: Período Regularización
D7: {{MES_1_INSTR_1}} | E7: {{MES_1_INSTR_2}} | F7: {{MES_1_INSTR_3}} | G7: {{MES_1_INSTR_4}} | H7: {{MES_1_INSTR_5}} | I7: {{MES_1_INSTR_6}} | J7: {{MES_1_INSTR_7}} | K7: {{MES_1_INSTR_8}}
A8: TP | B8: (puntaje máximo) | D8: 0 | E8: 0 | F8: 0 | G8: 0 | H8: 0 | I8: 0 | J8: 0 | K8: 0 | L8: =SUM(D8:K8) -> 0 | M8: =SUM(L8) -> 0
A9: 1 | B9: {{ALUMNO_NOMBRE}} | C9: =PLANTILLA_ETAPA_1!L9 -> 0 | D9: 0 | E9: 0 | F9: 0 | G9: 0 | H9: 0 | I9: 0 | J9: 0 | K9: 0 | L9: =SUM(D9:K9) -> 0 | M9: =L9 -> 0 | N9: 0 | O9: =SUM(C9+N9) -> 0 | P9: =IF((C9+N9)/2<=1.5,1,IF(N9=1,1,ROUND((C9+N9)/2,0))) -> 1
A10: 2 | B10: {{ALUMNO_NOMBRE}} | C10: =PLANTILLA_ETAPA_1!L10 -> 0 | D10: 0 | E10: 0 | F10: 0 | G10: 0 | H10: 0 | I10: 0 | J10: 0 | K10: 0 | L10: =SUM(D10:K10) -> 0 | M10: =L10 -> 0 | N10: 0 | O10: =SUM(C10+N10) -> 0 | P10: =IF((C10+N10)/2<=1.5,1,IF(N10=1,1,ROUND((C10+N10)/2,0))) -> 1
A11: 3 | B11: {{ALUMNO_NOMBRE}} | C11: =PLANTILLA_ETAPA_1!L11 -> 0 | D11: 0 | E11: 0 | F11: 0 | G11: 0 | H11: 0 | I11: 0 | J11: 0 | K11: 0 | L11: =SUM(D11:K11) -> 0 | M11: =L11 -> 0 | N11: 0 | O11: =SUM(C11+N11) -> 0 | P11: =IF((C11+N11)/2<=1.5,1,IF(N11=1,1,ROUND((C11+N11)/2,0))) -> 1
A12: 4 | B12: {{ALUMNO_NOMBRE}} | C12: =PLANTILLA_ETAPA_1!L12 -> 0 | D12: 0 | E12: 0 | F12: 0 | G12: 0 | H12: 0 | I12: 0 | J12: 0 | K12: 0 | L12: =SUM(D12:K12) -> 0 | M12: =L12 -> 0 | N12: 0 | O12: =SUM(C12+N12) -> 0 | P12: =IF((C12+N12)/2<=1.5,1,IF(N12=1,1,ROUND((C12+N12)/2,0))) -> 1
A13: 5 | B13: {{ALUMNO_NOMBRE}} | C13: =PLANTILLA_ETAPA_1!L13 -> 0 | D13: 0 | E13: 0 | F13: 0 | G13: 0 | H13: 0 | I13: 0 | J13: 0 | K13: 0 | L13: =SUM(D13:K13) -> 0 | M13: =L13 -> 0 | N13: 0 | O13: =SUM(C13+N13) -> 0 | P13: =IF((C13+N13)/2<=1.5,1,IF(N13=1,1,ROUND((C13+N13)/2,0))) -> 1
